{"uuid": "20ecdbe9-bd67-4e2e-97aa-7e769c73570b", "children": ["387aead6-3836-4fa4-8db7-10e55791a035"], "befores": [{"name": "setup_teardown", "status": "broken", "statusDetails": {"message": "urllib3.exceptions.MaxRetryError: HTTPConnectionPool(host='127.0.0.1', port=4723): Max retries exceeded with url: /wd/hub/session (Caused by NewConnectionError('<urllib3.connection.HTTPConnection object at 0x000001ACCAD059B0>: Failed to establish a new connection: [WinError 10061] 由于目标计算机积极拒绝，无法连接。',))\n", "trace": "  File \"D:\\software\\anaconda3\\envs\\job\\lib\\site-packages\\pluggy\\_callers.py\", line 39, in _multicall\n    res = hook_impl.function(*args)\n  File \"D:\\software\\anaconda3\\envs\\job\\lib\\site-packages\\_pytest\\fixtures.py\", line 1122, in pytest_fixture_setup\n    result = call_fixture_func(fixturefunc, request, kwargs)\n  File \"D:\\software\\anaconda3\\envs\\job\\lib\\site-packages\\_pytest\\fixtures.py\", line 917, in call_fixture_func\n    fixture_result = next(generator)\n  File \"D:\\code\\kyb_testProject\\test_case\\conftest.py\", line 11, in setup_teardown\n    driver = appium_desired()\n  File \"D:\\code\\kyb_testProject\\common\\desired_cap.py\", line 29, in appium_desired\n    driver = webdriver.Remote(f\"http://{str(data['ip'])}:{str(data['port'])}/wd/hub\", desired_cap)\n  File \"D:\\software\\anaconda3\\envs\\job\\lib\\site-packages\\appium\\webdriver\\webdriver.py\", line 155, in __init__\n    proxy\n  File \"D:\\software\\anaconda3\\envs\\job\\lib\\site-packages\\selenium\\webdriver\\remote\\webdriver.py\", line 157, in __init__\n    self.start_session(capabilities, browser_profile)\n  File \"D:\\software\\anaconda3\\envs\\job\\lib\\site-packages\\appium\\webdriver\\webdriver.py\", line 225, in start_session\n    response = self.execute(RemoteCommand.NEW_SESSION, parameters)\n  File \"D:\\software\\anaconda3\\envs\\job\\lib\\site-packages\\selenium\\webdriver\\remote\\webdriver.py\", line 319, in execute\n    response = self.command_executor.execute(driver_command, params)\n  File \"D:\\software\\anaconda3\\envs\\job\\lib\\site-packages\\selenium\\webdriver\\remote\\remote_connection.py\", line 374, in execute\n    return self._request(command_info[0], url, body=data)\n  File \"D:\\software\\anaconda3\\envs\\job\\lib\\site-packages\\selenium\\webdriver\\remote\\remote_connection.py\", line 397, in _request\n    resp = self._conn.request(method, url, body=body, headers=headers)\n  File \"D:\\software\\anaconda3\\envs\\job\\lib\\site-packages\\urllib3\\request.py\", line 79, in request\n    method, url, fields=fields, headers=headers, **urlopen_kw\n  File \"D:\\software\\anaconda3\\envs\\job\\lib\\site-packages\\urllib3\\request.py\", line 170, in request_encode_body\n    return self.urlopen(method, url, **extra_kw)\n  File \"D:\\software\\anaconda3\\envs\\job\\lib\\site-packages\\urllib3\\poolmanager.py\", line 376, in urlopen\n    response = conn.urlopen(method, u.request_uri, **kw)\n  File \"D:\\software\\anaconda3\\envs\\job\\lib\\site-packages\\urllib3\\connectionpool.py\", line 828, in urlopen\n    **response_kw\n  File \"D:\\software\\anaconda3\\envs\\job\\lib\\site-packages\\urllib3\\connectionpool.py\", line 828, in urlopen\n    **response_kw\n  File \"D:\\software\\anaconda3\\envs\\job\\lib\\site-packages\\urllib3\\connectionpool.py\", line 828, in urlopen\n    **response_kw\n  File \"D:\\software\\anaconda3\\envs\\job\\lib\\site-packages\\urllib3\\connectionpool.py\", line 788, in urlopen\n    method, url, error=e, _pool=self, _stacktrace=sys.exc_info()[2]\n  File \"D:\\software\\anaconda3\\envs\\job\\lib\\site-packages\\urllib3\\util\\retry.py\", line 592, in increment\n    raise MaxRetryError(_pool, url, error or ResponseError(cause))\n"}, "start": 1696047249220, "stop": 1696047258363}], "start": 1696047249220, "stop": 1696047258893}